<?xml version="1.0" encoding="utf-8"?>
<!-- =================================================================================== -->
<!-- |    This document was autogenerated by xacro from slider_2_0_urdf.urdf           | -->
<!-- |    EDITING THIS FILE BY HAND IS NOT RECOMMENDED                                 | -->
<!-- =================================================================================== -->
<!-- This URDF was automatically created by SolidWorks to URDF Exporter! Originally created by Stephen Brawner (brawner@gmail.com) 
     Commit Version: 1.6.0-1-g15f4949  Build Version: 1.6.7594.29634
     For more information, please see http://wiki.ros.org/sw_urdf_exporter -->




<robot name="slider_2_0_urdf" xmlns:xacro="http://ros.org/wiki/xacro">

  <xacro:include filename="$(find slider_2_0_urdf)/urdf/slider_2_0_.gazebo.xacro"/>

  <xacro:property name="r200_cam_rgb_px" value="0.005"/>
  <xacro:property name="r200_cam_rgb_py" value="0.018"/>
  <xacro:property name="r200_cam_rgb_pz" value="0.013"/>
  <xacro:property name="r200_cam_depth_offset" value="0.01"/>
  <xacro:property name="camera_link" value="0.05" /> <!-- Size of square 'camera' box -->


  <link name="world"/>

  <joint name="base_joint" type="fixed">
    <parent link="world"/>
    <child link="base_link" />
    <origin xyz="0 0 0.1" rpy="0 0 0"/>
  </joint>

  <link name="base_link">
    <inertial>
      <origin rpy="0 0 0" xyz="-0.0765324246620027 4.9441866434881E-09 0.610521382214614"/>
      <mass value="2.02469333344451"/>
      <inertia ixx="0.00376718384406223" ixy="-1.32565020465757E-07" ixz="-4.01564478042334E-06" iyy="0.00209460156447236" iyz="4.40200770634824E-10" izz="0.00255446895074592"/>
    </inertial>
    <visual>
      <origin rpy="0 0 0" xyz="0 0 0"/>
      <geometry>
        <mesh filename="package://slider_2_0_urdf/meshes/base_link.STL"/>
      </geometry>
      <material name="">
        <color rgba="0.752941176470588 0.752941176470588 0.752941176470588 1"/>
      </material>
    </visual>
    <collision>
      <origin rpy="0 0 0" xyz="0 0 0"/>
      <geometry>
        <mesh filename="package://slider_2_0_urdf/meshes/base_link.STL"/>
      </geometry>
    </collision>
  </link>
  
  <joint name="Left_Roll" type="revolute">
    <origin rpy="0 0 0" xyz="0 0.0749999999999995 0.591116132473436"/>
    <parent link="base_link"/>
    <child link="Left_Pitch_casing"/>
    <axis xyz="-1 0 0"/>
    <limit effort="48" lower="-0.35" upper="1.57" velocity="3.14"/>
  </joint>


  <link name="Left_Pitch_casing">
    <inertial>
      <origin rpy="0 0 0" xyz="-0.00637791780561047 0.000213831384279162 -1.17971270738038E-05"/>
      <mass value="1.12708372672221"/>
      <inertia ixx="0.00127122201055317" ixy="3.251218107481E-06" ixz="-4.35806917879868E-07" iyy="0.00204052239898519" iyz="-1.09023834178273E-05" izz="0.00154465658220456"/>
    </inertial>
    <visual>
      <origin rpy="0 0 0" xyz="0 0 0"/>
      <geometry>
        <mesh filename="package://slider_2_0_urdf/meshes/Left_Pitch_casing.STL"/>
      </geometry>
      <material name="">
        <color rgba="0.752941176470588 0.752941176470588 0.752941176470588 1"/>
      </material>
    </visual>
    <collision>
      <origin rpy="0 0 0" xyz="0 0 0"/>
      <geometry>
        <mesh filename="package://slider_2_0_urdf/meshes/Left_Pitch_casing.STL"/>
      </geometry>
    </collision>
  </link>


  <link name="Left_Slide_Casing">
    <inertial>
      <origin rpy="0 0 0" xyz="-0.0327747516406348 0.122616412056228 -0.00361644928605986"/>
      <mass value="1.04662003082236"/>
      <inertia ixx="0.00177420749171721" ixy="-8.43479504578415E-05" ixz="-8.76701595910206E-06" iyy="0.00185806902329562" iyz="-6.82808782201735E-05" izz="0.000846357923294892"/>
    </inertial>
    <visual>
      <origin rpy="0 0 0" xyz="0 0 0"/>
      <geometry>
        <mesh filename="package://slider_2_0_urdf/meshes/Left_Slide_Casing.STL"/>
      </geometry>
      <material name="">
        <color rgba="0.752941176470588 0.752941176470588 0.752941176470588 1"/>
      </material>
    </visual>
    <collision>
      <origin rpy="0 0 0" xyz="0 0 0"/>
      <geometry>
        <mesh filename="package://slider_2_0_urdf/meshes/Left_Slide_Casing.STL"/>
      </geometry>
    </collision>
  </link>

  <joint name="Left_Pitch" type="continuous">
    <origin rpy="0 0 0" xyz="0 0 0"/>
    <parent link="Left_Pitch_casing"/>
    <child link="Left_Slide_Casing"/>
    <axis xyz="0 -1 0"/>
    <limit effort="18" velocity="28"/>
  </joint>

  <link name="Left_Leg">
    <inertial>
      <origin rpy="0 0 0" xyz="0.00186620898483418 0.000816743884367782 -0.18632048172863"/>
      <mass value="1.85512765759961"/>
      <inertia ixx="0.0211099736585756" ixy="-4.54408700087738E-07" ixz="4.96451706876145E-05" iyy="0.0222717572103878" iyz="-1.07295394858633E-06" izz="0.00176289771304861"/>
    </inertial>
    <visual>
      <origin rpy="0 0 0" xyz="0 0 0"/>
      <geometry>
        <mesh filename="package://slider_2_0_urdf/meshes/Left_Leg.STL"/>
      </geometry>
      <material name="">
        <color rgba="0.752941176470588 0.752941176470588 0.752941176470588 1"/>
      </material>
    </visual>
    <collision>
      <origin rpy="0 0 0" xyz="0 0 0"/>
      <geometry>
        <mesh filename="package://slider_2_0_urdf/meshes/Left_Leg.STL"/>
      </geometry>
    </collision>
  </link>

  <joint name="Left_Slide" type="prismatic">
    <origin rpy="0 0 0" xyz="0 0.104199980302619 0"/>
    <parent link="Left_Slide_Casing"/>
    <child link="Left_Leg"/>
    <axis xyz="0 0 1"/>
    <limit effort="315" lower="-0.38" upper="0.41" velocity="0.56"/>
  </joint>

  <link name="Left_Foot_Pitch_Link">
    <inertial>
      <origin rpy="0 0 0" xyz="1.21192130775327E-08 -2.49876605518118E-09 -1.27517560954971E-08"/>
      <mass value="0.0141283854462189"/>
      <inertia ixx="1.59442165134791E-06" ixy="-6.21556747255079E-13" ixz="4.2489645445931E-13" iyy="1.60514807015652E-06" iyz="-2.53520076420128E-13" izz="1.51174921794827E-06"/>
    </inertial>
    <visual>
      <origin rpy="0 0 0" xyz="0 0 0"/>
      <geometry>
        <mesh filename="package://slider_2_0_urdf/meshes/Left_Foot_Pitch_Link.STL"/>
      </geometry>
      <material name="">
        <color rgba="0.752941176470588 0.752941176470588 0.752941176470588 1"/>
      </material>
    </visual>
    <collision>
      <origin rpy="0 0 0" xyz="0 0 0"/>
      <geometry>
        <mesh filename="package://slider_2_0_urdf/meshes/Left_Foot_Pitch_Link.STL"/>
      </geometry>
    </collision>
  </link>

  <joint name="Left_Foot_Pitch" type="continuous">
    <origin rpy="0 0 0" xyz="0 0 -0.591116132473436"/>
    <parent link="Left_Leg"/>
    <child link="Left_Foot_Pitch_Link"/>
    <axis xyz="0 -1 0"/>
    <limit effort="3" lower="-20" upper="20" velocity="28"/>
  </joint>

  <link name="Left_Foot">
    <inertial>
      <origin rpy="0 0 0" xyz="0.000859432497047443 0.00107826646655129 -0.0267222413448819"/>
      <mass value="0.412868497007575"/>
      <inertia ixx="0.000567578914748558" ixy="4.94015307643317E-09" ixz="5.19255230250368E-10" iyy="0.00109766785621675" iyz="-2.46630968177259E-06" izz="0.00164597144538111"/>
    </inertial>
    <visual>
      <origin rpy="0 0 0" xyz="0 0 0"/>
      <geometry>
        <mesh filename="package://slider_2_0_urdf/meshes/Left_Foot.STL"/>
      </geometry>
      <material name="">
        <color rgba="0.752941176470588 0.752941176470588 0.752941176470588 1"/>
      </material>
    </visual>
    <collision>
      <origin rpy="0 0 0" xyz="0 0 0"/>
      <geometry>
        <mesh filename="package://slider_2_0_urdf/meshes/Left_Foot.STL"/>
      </geometry>
    </collision>
  </link>

  <joint name="Left_Foot_Roll" type="continuous">
    <origin rpy="0 0 0" xyz="0 0 0"/>
    <parent link="Left_Foot_Pitch_Link"/>
    <child link="Left_Foot"/>
    <axis xyz="1 0 0"/>
    <limit effort="3" lower="-20" upper="20" velocity="28"/>
  </joint>

  <link name="Right_Pitch_casing">
    <inertial>
      <origin rpy="0 0 0" xyz="-0.00647797385747184 -0.000213976601378396 7.57552639663039E-06"/>
      <mass value="1.12708290379694"/>
      <inertia ixx="0.00127122339932927" ixy="-3.25951853220237E-06" ixz="3.70356391392349E-07" iyy="0.00204075639791425" iyz="-1.08915409219137E-06" izz="0.00154441812776377"/>
    </inertial>
    <visual>
      <origin rpy="0 0 0" xyz="0 0 0"/>
      <geometry>
        <mesh filename="package://slider_2_0_urdf/meshes/Right_Pitch_casing.STL"/>
      </geometry>
      <material name="">
        <color rgba="0.752941176470588 0.752941176470588 0.752941176470588 1"/>
      </material>
    </visual>
    <collision>
      <origin rpy="0 0 0" xyz="0 0 0"/>
      <geometry>
        <mesh filename="package://slider_2_0_urdf/meshes/Right_Pitch_casing.STL"/>
      </geometry>
    </collision>
  </link>

  <joint name="Right_Roll" type="revolute">
    <origin rpy="0 0 0" xyz="0 -0.0750000000000001 0.591116132473436"/>
    <parent link="base_link"/>
    <child link="Right_Pitch_casing"/>
    <axis xyz="-0.999999999999998 0 0"/>
    <limit effort="48" lower="-0.35" upper="1.57" velocity="3.14"/>
  </joint>

  <link name="Right_Slide_Casing">
    <inertial>
      <origin rpy="0 0 0" xyz="-0.0328747660964546 -0.122663946382931 0.0011908647649936"/>
      <mass value="1.04661946807414"/>
      <inertia ixx="0.00177420810309571" ixy="8.41579473719035E-05" ixz="1.04335551678863E-05" iyy="0.0018603724204831" iyz="-4.8223364131695E-05" izz="0.000844052487985306"/>
    </inertial>
    <visual>
      <origin rpy="0 0 0" xyz="0 0 0"/>
      <geometry>
        <mesh filename="package://slider_2_0_urdf/meshes/Right_Slide_Casing.STL"/>
      </geometry>
      <material name="">
        <color rgba="0.752941176470588 0.752941176470588 0.752941176470588 1"/>
      </material>
    </visual>
    <collision>
      <origin rpy="0 0 0" xyz="0 0 0"/>
      <geometry>
        <mesh filename="package://slider_2_0_urdf/meshes/Right_Slide_Casing.STL"/>
      </geometry>
    </collision>
  </link>

  <joint name="Right_Pitch" type="continuous">
    <origin rpy="0 0 0" xyz="0 0 0"/>
    <parent link="Right_Pitch_casing"/>
    <child link="Right_Slide_Casing"/>
    <axis xyz="0 1 0"/>
    <limit effort="18" velocity="28"/>
  </joint>

  <link name="Right_Leg">
    <inertial>
      <origin rpy="0 0 0" xyz="0.00186623868204826 0.000816728951440998 -0.1863204333875"/>
      <mass value="1.85512727949778"/>
      <inertia ixx="0.0211099734460687" ixy="-4.53803560950004E-07" ixz="4.9645491041883E-05" iyy="0.0222717558596174" iyz="-1.07278111285694E-06" izz="0.00176289645458729"/>
    </inertial>
    <visual>
      <origin rpy="0 0 0" xyz="0 0 0"/>
      <geometry>
        <mesh filename="package://slider_2_0_urdf/meshes/Right_Leg.STL"/>
      </geometry>
      <material name="">
        <color rgba="0.752941176470588 0.752941176470588 0.752941176470588 1"/>
      </material>
    </visual>
    <collision>
      <origin rpy="0 0 0" xyz="0 0 0"/>
      <geometry>
        <mesh filename="package://slider_2_0_urdf/meshes/Right_Leg.STL"/>
      </geometry>
    </collision>
  </link>

  <joint name="Right_Slide" type="prismatic">
    <origin rpy="0 0 0" xyz="0 -0.104199980302619 0"/>
    <parent link="Right_Slide_Casing"/>
    <child link="Right_Leg"/>
    <axis xyz="0 0 1"/>
    <limit effort="315" lower="-0.38" upper="0.41" velocity="0.56"/>
  </joint>
  <link name="Right_Foot_Pitch_Link">
    <inertial>
      <origin rpy="0 0 0" xyz="1.13095142105502E-08 -2.21952002055215E-08 -1.27526379456455E-08"/>
      <mass value="0.014128385446219"/>
      <inertia ixx="1.59442165134791E-06" ixy="-6.21556748216398E-13" ixz="4.24896453989181E-13" iyy="1.60514807015652E-06" iyz="-2.5352007436654E-13" izz="1.51174921794827E-06"/>
    </inertial>
    <visual>
      <origin rpy="0 0 0" xyz="0 0 0"/>
      <geometry>
        <mesh filename="package://slider_2_0_urdf/meshes/Right_Foot_Pitch_Link.STL"/>
      </geometry>
      <material name="">
        <color rgba="0.752941176470588 0.752941176470588 0.752941176470588 1"/>
      </material>
    </visual>
    <collision>
      <origin rpy="0 0 0" xyz="0 0 0"/>
      <geometry>
        <mesh filename="package://slider_2_0_urdf/meshes/Right_Foot_Pitch_Link.STL"/>
      </geometry>
    </collision>
  </link>
  <joint name="Right_Foot_Pitch" type="continuous">
    <origin rpy="0 0 0" xyz="0 0 -0.591116132473436"/>
    <parent link="Right_Leg"/>
    <child link="Right_Foot_Pitch_Link"/>
    <axis xyz="0 1 0"/>
    <limit effort="3" lower="-20" upper="20" velocity="28"/>
  </joint>
  <link name="Right_Foot">
    <inertial>
      <origin rpy="0 0 0" xyz="0.000859431687348554 0.00107824677010171 -0.0267222413457578"/>
      <mass value="0.412868497007574"/>
      <inertia ixx="0.000567578914748551" ixy="4.94015307639139E-09" ixz="5.19255230283473E-10" iyy="0.00109766785621674" iyz="-2.46630968177226E-06" izz="0.0016459714453811"/>
    </inertial>
    <visual>
      <origin rpy="0 0 0" xyz="0 0 0"/>
      <geometry>
        <mesh filename="package://slider_2_0_urdf/meshes/Right_Foot.STL"/>
      </geometry>
      <material name="">
        <color rgba="0.752941176470588 0.752941176470588 0.752941176470588 1"/>
      </material>
    </visual>
    <collision>
      <origin rpy="0 0 0" xyz="0 0 0"/>
      <geometry>
        <mesh filename="package://slider_2_0_urdf/meshes/Right_Foot.STL"/>
      </geometry>
    </collision>
  </link>
  <joint name="Right_Foot_Roll" type="continuous">
    <origin rpy="0 0 0" xyz="0 0 0"/>
    <parent link="Right_Foot_Pitch_Link"/>
    <child link="Right_Foot"/>
    <axis xyz="1 0 0"/>
    <limit effort="3" lower="-20" upper="20" velocity="28"/>
  </joint>

  <joint name="imu_joint" type="fixed">
    <parent link="base_link"/>
    <child link="imu_link"/>
    <origin xyz="-0.0765324246620027 4.9441866434881E-09 0.610521382214614" rpy="0 0 0"/>
  </joint>

  <link name="imu_link"/>



  <joint name="camera_joint" type="fixed">
    <axis xyz="0 0 0" />
    <!--origin xyz="0.12 0 0.65" rpy="0 0.87  0"/-->
    <origin xyz="0.12 0 0.65" rpy="0 0.7854 0"/>
    <parent link="base_link"/>
    <child link="camera_link"/>
  </joint>

  <!-- Camera -->
  <link name="camera_link">
    <visual>
    <geometry>
      <box size="0.064 0.121 0.0381" />
    </geometry>
    <material name="Blue" />
  </visual>
  </link>

     <!-- The point cloud pose error is displayed in RVIZ, and an empty link and an empty joint are added here to adjust the point cloud tf pose -->
  <link name="camera_link_fake"></link>
  <joint name="camera_joint_fake" type="fixed">
    <origin xyz="0 0 0" rpy="-1.5708 0 -1.5708 "/>
    <parent link="camera_link"/>
    <child link="camera_link_fake"/>
  </joint>


</robot>
